<?xml version="1.0" encoding="UTF-8"?>
<!-- Generated by org.testng.reporters.JUnitXMLReporter -->
<testsuite hostname="Me-Pc" ignored="1" name="Default test" tests="10" failures="1" timestamp="07 Dec 2018 09:59:31 GMT" time="5.128" errors="0">
  <testcase name="bTest3" time="0.01" classname="com.maven.testng1.BTest1"/>
  <testcase name="bTest3" time="0.003" classname="com.maven.testng1.BTest1"/>
  <testcase name="bTest3" time="0.002" classname="com.maven.testng1.BTest1"/>
  <testcase name="bTest3" time="0.001" classname="com.maven.testng1.BTest1"/>
  <testcase name="bTest3" time="0.001" classname="com.maven.testng1.BTest1"/>
  <testcase name="bTest3" time="0.002" classname="com.maven.testng1.BTest1"/>
  <testcase name="bTest3" time="0.001" classname="com.maven.testng1.BTest1"/>
  <testcase name="bTest3" time="0.002" classname="com.maven.testng1.BTest1"/>
  <testcase name="bTest4" time="0.006" classname="com.maven.testng1.BTest1"/>
  <testcase name="bTest2" time="5.011" classname="com.maven.testng1.BTest1">
    <failure type="org.testng.internal.thread.ThreadTimeoutException" message="Method com.maven.testng1.BTest1.bTest2() didn&amp;apos;t finish within the time-out 5000">
      <![CDATA[org.testng.internal.thread.ThreadTimeoutException: Method com.maven.testng1.BTest1.bTest2() didn't finish within the time-out 5000at java.util.concurrent.FutureTask.finishCompletion(Unknown Source)at java.util.concurrent.FutureTask.setException(Unknown Source)at java.util.concurrent.FutureTask.run(Unknown Source)at java.util.concurrent.ThreadPoolExecutor.runWorker(Unknown Source)at java.util.concurrent.ThreadPoolExecutor$Worker.run(Unknown Source)at java.lang.Thread.run(Unknown Source)]]>
    </failure>
  </testcase> <!-- bTest2 -->
  <testcase name="bTest1" time="0.0" classname="com.maven.testng1.BTest1">
    <ignored/>
  </testcase> <!-- bTest1 -->
</testsuite> <!-- Default test -->
